Workbook

Sheet Dashboard
U4: Current Year | X4: ROA = 15% | Y4: 0.15
U5: NPM | V5: TAT | X5: Step Size | Y5: 0.02
T6: A | U6: =D47 -> #DIV/0! | V6: =D54 -> #DIV/0!
T7: B | U7: =D48 -> #DIV/0! | V7: =D55 -> #DIV/0!
T8: C | U8: =D49 -> #DIV/0! | V8: =D56 -> #DIV/0! | X8: NPM | Y8: TAT
T9: D | U9: =D50 -> #DIV/0! | V9: =D57 -> #DIV/0! | X9: 0.4 | Y9: =$Y$4/X9 -> 0.375
T10: E | U10: =D51 -> #DIV/0! | V10: =D58 -> #DIV/0! | X10: =X9-$Y$5 -> 0.38 | Y10: =$Y$4/X10 -> 0.39473684
T11: F | U11: =D52 -> #DIV/0! | V11: =D59 -> #DIV/0! | X11: =X10-$Y$5 -> 0.36 | Y11: =$Y$4/X11 -> 0.41666667
T12: G | U12: =D53 -> #DIV/0! | V12: =D60 -> #DIV/0! | X12: =X11-$Y$5 -> 0.34 | Y12: =$Y$4/X12 -> 0.44117647
X13: =X12-$Y$5 -> 0.32 | Y13: =$Y$4/X13 -> 0.46875
X14: =X13-$Y$5 -> 0.3 | Y14: =$Y$4/X14 -> 0.5
X15: =X14-$Y$5 -> 0.28 | Y15: =$Y$4/X15 -> 0.53571429
X16: =X15-$Y$5 -> 0.26 | Y16: =$Y$4/X16 -> 0.57692308
X17: =X16-$Y$5 -> 0.24 | Y17: =$Y$4/X17 -> 0.625
X18: =X17-$Y$5 -> 0.22 | Y18: =$Y$4/X18 -> 0.68181818
X19: =X18-$Y$5 -> 0.2 | Y19: =$Y$4/X19 -> 0.75
X20: =X19-$Y$5 -> 0.18 | Y20: =$Y$4/X20 -> 0.83333333
X21: =X20-$Y$5 -> 0.16 | Y21: =$Y$4/X21 -> 0.9375
X22: =X21-$Y$5 -> 0.14 | Y22: =$Y$4/X22 -> 1.0714286
X23: =X22-$Y$5 -> 0.12 | Y23: =$Y$4/X23 -> 1.25
X24: =X23-$Y$5 -> 0.1 | Y24: =$Y$4/X24 -> 1.5
... X28: =X27-$Y$5 -> 0.02 | Y28: =$Y$4/X28 -> 7.5
A46: Industry | B46: Measure | C46: Firm | D46: Year 1 | E46: Year 2 | F46: Year 3 | G46: Year 4 | H46: Year 5 | I46: Year 6 | J46: Year 7 | K46: Year 8
A47: Section 1 | B47: Net Profit Margin | C47: A | D47: ='Year 1'!$D$44 -> #DIV/0! | E47: ='Year 2'!$D$44 -> #DIV/0! | F47: ='Year 3'!$D$44 -> #DIV/0! | G47: ='Year 4'!$D$44 -> #DIV/0! | H47: ='Year 5'!$D$44 -> #DIV/0! | I47: ='Year 6'!$D$44 -> #DIV/0! | J47: ='Year 7'!$D$44 -> #DIV/0! | K47: ='Year 8'!$D$44 -> #DIV/0!
A48: Section 1 | B48: Net Profit Margin | C48: B | D48: ='Year 1'!$E$44 -> #DIV/0! | E48: ='Year 2'!$E$44 -> #DIV/0! | F48: ='Year 3'!$E$44 -> #DIV/0! | G48: ='Year 4'!$E$44 -> #DIV/0! | H48: ='Year 5'!$E$44 -> #DIV/0! | I48: ='Year 6'!$E$44 -> #DIV/0! | J48: ='Year 7'!$E$44 -> #DIV/0! | K48: ='Year 8'!$E$44 -> #DIV/0!
A49: Section 1 | B49: Net Profit Margin | C49: C | D49: ='Year 1'!$F$44 -> #DIV/0! | E49: ='Year 2'!$F$44 -> #DIV/0! | F49: ='Year 3'!$F$44 -> #DIV/0! | G49: ='Year 4'!$F$44 -> #DIV/0! | H49: ='Year 5'!$F$44 -> #DIV/0! | I49: ='Year 6'!$F$44 -> #DIV/0! | J49: ='Year 7'!$F$44 -> #DIV/0! | K49: ='Year 8'!$F$44 -> #DIV/0!
A50: Section 1 | B50: Net Profit Margin | C50: D | D50: ='Year 1'!$G$44 -> #DIV/0! | E50: ='Year 2'!$G$44 -> #DIV/0! | F50: ='Year 3'!$G$44 -> #DIV/0! | G50: ='Year 4'!$G$44 -> #DIV/0! | H50: ='Year 5'!$G$44 -> #DIV/0! | I50: ='Year 6'!$G$44 -> #DIV/0! | J50: ='Year 7'!$G$44 -> #DIV/0! | K50: ='Year 8'!$G$44 -> #DIV/0!
A51: Section 1 | B51: Net Profit Margin | C51: E | D51: ='Year 1'!$H$44 -> #DIV/0! | E51: ='Year 2'!$H$44 -> #DIV/0! | F51: ='Year 3'!$H$44 -> #DIV/0! | G51: ='Year 4'!$H$44 -> #DIV/0! | H51: ='Year 5'!$H$44 -> #DIV/0! | I51: ='Year 6'!$H$44 -> #DIV/0! | J51: ='Year 7'!$H$44 -> #DIV/0! | K51: ='Year 8'!$H$44 -> #DIV/0!
A52: Section 1 | B52: Net Profit Margin | C52: F | D52: ='Year 1'!$I$44 -> #DIV/0! | E52: ='Year 2'!$I$44 -> #DIV/0! | F52: ='Year 3'!$I$44 -> #DIV/0! | G52: ='Year 4'!$I$44 -> #DIV/0! | H52: ='Year 5'!$I$44 -> #DIV/0! | I52: ='Year 6'!$I$44 -> #DIV/0! | J52: ='Year 7'!$I$44 -> #DIV/0! | K52: ='Year 8'!$I$44 -> #DIV/0!
A53: Section 1 | B53: Net Profit Margin | C53: G | D53: ='Year 1'!$J$44 -> #DIV/0! | E53: ='Year 2'!$J$44 -> #DIV/0! | F53: ='Year 3'!$J$44 -> #DIV/0! | G53: ='Year 4'!$J$44 -> #DIV/0! | H53: ='Year 5'!$J$44 -> #DIV/0! | I53: ='Year 6'!$J$44 -> #DIV/0! | J53: ='Year 7'!$J$44 -> #DIV/0! | K53: ='Year 8'!$J$44 -> #DIV/0!
A54: Section 1 | B54: Total Asset Turnover | C54: A | D54: ='Year 1'!$D$57 -> #DIV/0! | E54: ='Year 2'!$D$57 -> #DIV/0! | F54: ='Year 3'!$D$57 -> #DIV/0! | G54: ='Year 4'!$D$57 -> #DIV/0! | H54: ='Year 5'!$D$57 -> #DIV/0! | I54: ='Year 6'!$D$57 -> #DIV/0! | J54: ='Year 7'!$D$57 -> #DIV/0! | K54: ='Year 8'!$D$57 -> #DIV/0!
A55: Section 1 | B55: Total Asset Turnover | C55: B | D55: ='Year 1'!$E$57 -> #DIV/0! | E55: ='Year 2'!$E$57 -> #DIV/0! | F55: ='Year 3'!$E$57 -> #DIV/0! | G55: ='Year 4'!$E$57 -> #DIV/0! | H55: ='Year 5'!$E$57 -> #DIV/0! | I55: ='Year 6'!$E$57 -> #DIV/0! | J55: ='Year 7'!$E$57 -> #DIV/0! | K55: ='Year 8'!$E$57 -> #DIV/0!
A56: Section 1 | B56: Total Asset Turnover | C56: C | D56: ='Year 1'!$F$57 -> #DIV/0! | E56: ='Year 2'!$F$57 -> #DIV/0! | F56: ='Year 3'!$F$57 -> #DIV/0! | G56: ='Year 4'!$F$57 -> #DIV/0! | H56: ='Year 5'!$F$57 -> #DIV/0! | I56: ='Year 6'!$F$57 -> #DIV/0! | J56: ='Year 7'!$F$57 -> #DIV/0! | K56: ='Year 8'!$F$57 -> #DIV/0!
A57: Section 1 | B57: Total Asset Turnover | C57: D | D57: ='Year 1'!$G$57 -> #DIV/0! | E57: ='Year 2'!$G$57 -> #DIV/0! | F57: ='Year 3'!$G$57 -> #DIV/0! | G57: ='Year 4'!$G$57 -> #DIV/0! | H57: ='Year 5'!$G$57 -> #DIV/0! | I57: ='Year 6'!$G$57 -> #DIV/0! | J57: ='Year 7'!$G$57 -> #DIV/0! | K57: ='Year 8'!$G$57 -> #DIV/0!
A58: Section 1 | B58: Total Asset Turnover | C58: E | D58: ='Year 1'!$H$57 -> #DIV/0! | E58: ='Year 2'!$H$57 -> #DIV/0! | F58: ='Year 3'!$H$57 -> #DIV/0! | G58: ='Year 4'!$H$57 -> #DIV/0! | H58: ='Year 5'!$H$57 -> #DIV/0! | I58: ='Year 6'!$H$57 -> #DIV/0! | J58: ='Year 7'!$H$57 -> #DIV/0! | K58: ='Year 8'!$H$57 -> #DIV/0!
A59: Section 1 | B59: Total Asset Turnover | C59: F | D59: ='Year 1'!$I$57 -> #DIV/0! | E59: ='Year 2'!$I$57 -> #DIV/0! | F59: ='Year 3'!$I$57 -> #DIV/0! | G59: ='Year 4'!$I$57 -> #DIV/0! | H59: ='Year 5'!$I$57 -> #DIV/0! | I59: ='Year 6'!$I$57 -> #DIV/0! | J59: ='Year 7'!$I$57 -> #DIV/0! | K59: ='Year 8'!$I$57 -> #DIV/0!
A60: Section 1 | B60: Total Asset Turnover | C60: G | D60: ='Year 1'!$J$57 -> #DIV/0! | E60: ='Year 2'!$J$57 -> #DIV/0! | F60: ='Year 3'!$J$57 -> #DIV/0! | G60: ='Year 4'!$J$57 -> #DIV/0! | H60: ='Year 5'!$J$57 -> #DIV/0! | I60: ='Year 6'!$J$57 -> #DIV/0! | J60: ='Year 7'!$J$57 -> #DIV/0! | K60: ='Year 8'!$J$57 -> #DIV/0!
A61: Section 1 | B61: Equity Multiplier | C61: A | D61: ='Year 1'!$D$48 -> #DIV/0! | E61: ='Year 2'!$D$48 -> #DIV/0! | F61: ='Year 3'!$D$48 -> #DIV/0! | G61: ='Year 4'!$D$48 -> #DIV/0! | H61: ='Year 5'!$D$48 -> #DIV/0! | I61: ='Year 6'!$D$48 -> #DIV/0! | J61: ='Year 7'!$D$48 -> #DIV/0! | K61: ='Year 8'!$D$48 -> #DIV/0!
A62: Section 1 | B62: Equity Multiplier | C62: B | D62: ='Year 1'!$E$48 -> #DIV/0! | E62: ='Year 2'!$E$48 -> #DIV/0! | F62: ='Year 3'!$E$48 -> #DIV/0! | G62: ='Year 4'!$E$48 -> #DIV/0! | H62: ='Year 5'!$E$48 -> #DIV/0! | I62: ='Year 6'!$E$48 -> #DIV/0! | J62: ='Year 7'!$E$48 -> #DIV/0! | K62: ='Year 8'!$E$48 -> #DIV/0!
A63: Section 1 | B63: Equity Multiplier | C63: C | D63: ='Year 1'!$F$48 -> #DIV/0! | E63: ='Year 2'!$F$48 -> #DIV/0! | F63: ='Year 3'!$F$48 -> #DIV/0! | G63: ='Year 4'!$F$48 -> #DIV/0! | H63: ='Year 5'!$F$48 -> #DIV/0! | I63: ='Year 6'!$F$48 -> #DIV/0! | J63: ='Year 7'!$F$48 -> #DIV/0! | K63: ='Year 8'!$F$48 -> #DIV/0!
...

Sheet Year 1
B3: Income Statement | C3: MILLIONS | D3: FIRM A | E3: FIRM B | F3: FIRM C | G3: FIRM D | H3: FIRM E | I3: FIRM F | J3: FIRM G
C4: Sales
C5: Cost of Goods Sold
C6: Gross Margin
C7: Marketing
C8: Research and Development
C9: General and Administrative
C10: Income from Operations
C11: Interest Income
C12: Interest Expense
C13: Extraordinary Items
C14: Income before Tax
C15: Less Tax @ 35%
... C17: Dividends Paid
B18: Balance Sheet | C18: MILLIONS | D18: FIRM A | E18: FIRM B | F18: FIRM C | G18: FIRM D | H18: FIRM E | I18: FIRM F | J18: FIRM G
B19: Assets | C19: Cash
C20: Short-term securities
C21: Receivables
C22: Inventory
C23: Plant and Equipment
C24: Accumulated Depreciation
C25: Total Assets
B26: Liabilities | C26: Accounts Payable
C27: Short Term Debt
C28: Long Term Debt
C29: Total Liabilities
B30: Equity | C30: Stock ($1 par)
C31: Add'l Paid in Cap.
C32: Retained Earnings
C33: Treasury Stock
C34: Total Equity
B35: Inventory Detail | C35: Beg. Inventory
C36: End. Inventory
C37: Avg. Inventory | D37: =SUM(D35:D36)/2 -> 0 | E37: =SUM(E35:E36)/2 -> 0 | F37: =SUM(F35:F36)/2 -> 0 | G37: =SUM(G35:G36)/2 -> 0 | H37: =SUM(H35:H36)/2 -> 0 | I37: =SUM(I35:I36)/2 -> 0 | J37: =SUM(J35:J36)/2 -> 0
B38: Cash Flow | C38: MILLIONS | D38: FIRM A | E38: FIRM B | F38: FIRM C | G38: FIRM D | H38: FIRM E | I38: FIRM F | J38: FIRM G
C39: Net Cash from Operations
C40: Net investment
B41: Ratios | D41: FIRM A | E41: FIRM B | F41: FIRM C | G41: FIRM D | H41: FIRM E | I41: FIRM F | J41: FIRM G
B42: Profitability | C42: Gross Profit Margin | D42: =D6/D4 -> #DIV/0! | E42: =E6/E4 -> #DIV/0! | F42: =F6/F4 -> #DIV/0! | G42: =G6/G4 -> #DIV/0! | H42: =H6/H4 -> #DIV/0! | I42: =I6/I4 -> #DIV/0! | J42: =J6/J4 -> #DIV/0!
C43: Operating Profit Margin | D43: =D10/D4 -> #DIV/0! | E43: =E10/E4 -> #DIV/0! | F43: =F10/F4 -> #DIV/0! | G43: =G10/G4 -> #DIV/0! | H43: =H10/H4 -> #DIV/0! | I43: =I10/I4 -> #DIV/0! | J43: =J10/J4 -> #DIV/0!
...

Sheet Year 2
B3: Income Statement | C3: MILLIONS | D3: FIRM A | E3: FIRM B | F3: FIRM C | G3: FIRM D | H3: FIRM E | I3: FIRM F | J3: FIRM G
C4: Sales
C5: Cost of Goods Sold
C6: Gross Margin
C7: Marketing
C8: Research and Development
C9: General and Administrative
C10: Income from Operations
C11: Interest Income
C12: Interest Expense
C13: Extraordinary Items
C14: Income before Tax
C15: Less Tax @ 35%
... C17: Dividends Paid
B18: Balance Sheet | C18: MILLIONS | D18: FIRM A | E18: FIRM B | F18: FIRM C | G18: FIRM D | H18: FIRM E | I18: FIRM F | J18: FIRM G
B19: Assets | C19: Cash
C20: Short-term securities
C21: Receivables
C22: Inventory
C23: Plant and Equipment
C24: Accumulated Depreciation
C25: Total Assets
B26: Liabilities | C26: Accounts Payable
C27: Short Term Debt
C28: Long Term Debt
C29: Total Liabilities
B30: Equity | C30: Stock ($1 par)
C31: Add'l Paid in Cap.
C32: Retained Earnings
C33: Treasury Stock
C34: Total Equity
B35: Inventory Detail | C35: Beg. Inventory
C36: End. Inventory
C37: Avg. Inventory | D37: =SUM(D35:D36)/2 -> 0 | E37: =SUM(E35:E36)/2 -> 0 | F37: =SUM(F35:F36)/2 -> 0 | G37: =SUM(G35:G36)/2 -> 0 | H37: =SUM(H35:H36)/2 -> 0 | I37: =SUM(I35:I36)/2 -> 0 | J37: =SUM(J35:J36)/2 -> 0
B38: Cash Flow | C38: MILLIONS | D38: FIRM A | E38: FIRM B | F38: FIRM C | G38: FIRM D | H38: FIRM E | I38: FIRM F | J38: FIRM G
C39: Net Cash from Operations
C40: Net investment
B41: Ratios | D41: FIRM A | E41: FIRM B | F41: FIRM C | G41: FIRM D | H41: FIRM E | I41: FIRM F | J41: FIRM G
B42: Profitability | C42: Gross Profit Margin | D42: =D6/D4 -> #DIV/0! | E42: =E6/E4 -> #DIV/0! | F42: =F6/F4 -> #DIV/0! | G42: =G6/G4 -> #DIV/0! | H42: =H6/H4 -> #DIV/0! | I42: =I6/I4 -> #DIV/0! | J42: =J6/J4 -> #DIV/0!
C43: Operating Profit Margin | D43: =D10/D4 -> #DIV/0! | E43: =E10/E4 -> #DIV/0! | F43: =F10/F4 -> #DIV/0! | G43: =G10/G4 -> #DIV/0! | H43: =H10/H4 -> #DIV/0! | I43: =I10/I4 -> #DIV/0! | J43: =J10/J4 -> #DIV/0!
...

Sheet Year 3
B3: Income Statement | C3: MILLIONS | D3: FIRM A | E3: FIRM B | F3: FIRM C | G3: FIRM D | H3: FIRM E | I3: FIRM F | J3: FIRM G
C4: Sales
C5: Cost of Goods Sold
C6: Gross Margin
C7: Marketing
C8: Research and Development
C9: General and Administrative
C10: Income from Operations
C11: Interest Income
C12: Interest Expense
C13: Extraordinary Items
C14: Income before Tax
C15: Less Tax @ 35%
... C17: Dividends Paid
B18: Balance Sheet | C18: MILLIONS | D18: FIRM A | E18: FIRM B | F18: FIRM C | G18: FIRM D | H18: FIRM E | I18: FIRM F | J18: FIRM G
B19: Assets | C19: Cash
C20: Short-term securities
C21: Receivables
C22: Inventory
C23: Plant and Equipment
C24: Accumulated Depreciation
C25: Total Assets
B26: Liabilities | C26: Accounts Payable
C27: Short Term Debt
C28: Long Term Debt
C29: Total Liabilities
B30: Equity | C30: Stock ($1 par)
C31: Add'l Paid in Cap.
C32: Retained Earnings
C33: Treasury Stock
C34: Total Equity
B35: Inventory Detail | C35: Beg. Inventory
C36: End. Inventory
C37: Avg. Inventory | D37: =SUM(D35:D36)/2 -> 0 | E37: =SUM(E35:E36)/2 -> 0 | F37: =SUM(F35:F36)/2 -> 0 | G37: =SUM(G35:G36)/2 -> 0 | H37: =SUM(H35:H36)/2 -> 0 | I37: =SUM(I35:I36)/2 -> 0 | J37: =SUM(J35:J36)/2 -> 0
B38: Cash Flow | C38: MILLIONS | D38: FIRM A | E38: FIRM B | F38: FIRM C | G38: FIRM D | H38: FIRM E | I38: FIRM F | J38: FIRM G
C39: Net Cash from Operations
C40: Net investment
B41: Ratios | D41: FIRM A | E41: FIRM B | F41: FIRM C | G41: FIRM D | H41: FIRM E | I41: FIRM F | J41: FIRM G
B42: Profitability | C42: Gross Profit Margin | D42: =D6/D4 -> #DIV/0! | E42: =E6/E4 -> #DIV/0! | F42: =F6/F4 -> #DIV/0! | G42: =G6/G4 -> #DIV/0! | H42: =H6/H4 -> #DIV/0! | I42: =I6/I4 -> #DIV/0! | J42: =J6/J4 -> #DIV/0!
C43: Operating Profit Margin | D43: =D10/D4 -> #DIV/0! | E43: =E10/E4 -> #DIV/0! | F43: =F10/F4 -> #DIV/0! | G43: =G10/G4 -> #DIV/0! | H43: =H10/H4 -> #DIV/0! | I43: =I10/I4 -> #DIV/0! | J43: =J10/J4 -> #DIV/0!
...

Sheet Year 4
B3: Income Statement | C3: MILLIONS | D3: FIRM A | E3: FIRM B | F3: FIRM C | G3: FIRM D | H3: FIRM E | I3: FIRM F | J3: FIRM G
C4: Sales
C5: Cost of Goods Sold
C6: Gross Margin
C7: Marketing
C8: Research and Development
C9: General and Administrative
C10: Income from Operations
C11: Interest Income
C12: Interest Expense
C13: Extraordinary Items
C14: Income before Tax
C15: Less Tax @ 35%
... C17: Dividends Paid
B18: Balance Sheet | C18: MILLIONS | D18: FIRM A | E18: FIRM B | F18: FIRM C | G18: FIRM D | H18: FIRM E | I18: FIRM F | J18: FIRM G
B19: Assets | C19: Cash
C20: Short-term securities
C21: Receivables
C22: Inventory
C23: Plant and Equipment
C24: Accumulated Depreciation
C25: Total Assets
B26: Liabilities | C26: Accounts Payable
C27: Short Term Debt
C28: Long Term Debt
C29: Total Liabilities
B30: Equity | C30: Stock ($1 par)
C31: Add'l Paid in Cap.
C32: Retained Earnings
C33: Treasury Stock
C34: Total Equity
B35: Inventory Detail | C35: Beg. Inventory
C36: End. Inventory
C37: Avg. Inventory | D37: =SUM(D35:D36)/2 -> 0 | E37: =SUM(E35:E36)/2 -> 0 | F37: =SUM(F35:F36)/2 -> 0 | G37: =SUM(G35:G36)/2 -> 0 | H37: =SUM(H35:H36)/2 -> 0 | I37: =SUM(I35:I36)/2 -> 0 | J37: =SUM(J35:J36)/2 -> 0
B38: Cash Flow | C38: MILLIONS | D38: FIRM A | E38: FIRM B | F38: FIRM C | G38: FIRM D | H38: FIRM E | I38: FIRM F | J38: FIRM G
C39: Net Cash from Operations
C40: Net investment
B41: Ratios | D41: FIRM A | E41: FIRM B | F41: FIRM C | G41: FIRM D | H41: FIRM E | I41: FIRM F | J41: FIRM G
B42: Profitability | C42: Gross Profit Margin | D42: =D6/D4 -> #DIV/0! | E42: =E6/E4 -> #DIV/0! | F42: =F6/F4 -> #DIV/0! | G42: =G6/G4 -> #DIV/0! | H42: =H6/H4 -> #DIV/0! | I42: =I6/I4 -> #DIV/0! | J42: =J6/J4 -> #DIV/0!
C43: Operating Profit Margin | D43: =D10/D4 -> #DIV/0! | E43: =E10/E4 -> #DIV/0! | F43: =F10/F4 -> #DIV/0! | G43: =G10/G4 -> #DIV/0! | H43: =H10/H4 -> #DIV/0! | I43: =I10/I4 -> #DIV/0! | J43: =J10/J4 -> #DIV/0!
...

Sheet Year 5
B3: Income Statement | C3: MILLIONS | D3: FIRM A | E3: FIRM B | F3: FIRM C | G3: FIRM D | H3: FIRM E | I3: FIRM F | J3: FIRM G
C4: Sales
C5: Cost of Goods Sold
C6: Gross Margin
C7: Marketing
C8: Research and Development
C9: General and Administrative
C10: Income from Operations
C11: Interest Income
C12: Interest Expense
C13: Extraordinary Items
C14: Income before Tax
C15: Less Tax @ 35%
... C17: Dividends Paid
B18: Balance Sheet | C18: MILLIONS | D18: FIRM A | E18: FIRM B | F18: FIRM C | G18: FIRM D | H18: FIRM E | I18: FIRM F | J18: FIRM G
B19: Assets | C19: Cash
C20: Short-term securities
C21: Receivables
C22: Inventory
C23: Plant and Equipment
C24: Accumulated Depreciation
C25: Total Assets
B26: Liabilities | C26: Accounts Payable
C27: Short Term Debt
C28: Long Term Debt
C29: Total Liabilities
B30: Equity | C30: Stock ($1 par)
C31: Add'l Paid in Cap.
C32: Retained Earnings
C33: Treasury Stock
C34: Total Equity
B35: Inventory Detail | C35: Beg. Inventory
C36: End. Inventory
C37: Avg. Inventory | D37: =SUM(D35:D36)/2 -> 0 | E37: =SUM(E35:E36)/2 -> 0 | F37: =SUM(F35:F36)/2 -> 0 | G37: =SUM(G35:G36)/2 -> 0 | H37: =SUM(H35:H36)/2 -> 0 | I37: =SUM(I35:I36)/2 -> 0 | J37: =SUM(J35:J36)/2 -> 0
B38: Cash Flow | C38: MILLIONS | D38: FIRM A | E38: FIRM B | F38: FIRM C | G38: FIRM D | H38: FIRM E | I38: FIRM F | J38: FIRM G
C39: Net Cash from Operations
C40: Net investment
B41: Ratios | D41: FIRM A | E41: FIRM B | F41: FIRM C | G41: FIRM D | H41: FIRM E | I41: FIRM F | J41: FIRM G
B42: Profitability | C42: Gross Profit Margin | D42: =D6/D4 -> #DIV/0! | E42: =E6/E4 -> #DIV/0! | F42: =F6/F4 -> #DIV/0! | G42: =G6/G4 -> #DIV/0! | H42: =H6/H4 -> #DIV/0! | I42: =I6/I4 -> #DIV/0! | J42: =J6/J4 -> #DIV/0!
C43: Operating Profit Margin | D43: =D10/D4 -> #DIV/0! | E43: =E10/E4 -> #DIV/0! | F43: =F10/F4 -> #DIV/0! | G43: =G10/G4 -> #DIV/0! | H43: =H10/H4 -> #DIV/0! | I43: =I10/I4 -> #DIV/0! | J43: =J10/J4 -> #DIV/0!
...

Sheet Year 6
B3: Income Statement | C3: MILLIONS | D3: FIRM A | E3: FIRM B | F3: FIRM C | G3: FIRM D | H3: FIRM E | I3: FIRM F | J3: FIRM G
C4: Sales
C5: Cost of Goods Sold
C6: Gross Margin
C7: Marketing
C8: Research and Development
C9: General and Administrative
C10: Income from Operations
C11: Interest Income
C12: Interest Expense
C13: Extraordinary Items
C14: Income before Tax
C15: Less Tax @ 35%
... C17: Dividends Paid
B18: Balance Sheet | C18: MILLIONS | D18: FIRM A | E18: FIRM B | F18: FIRM C | G18: FIRM D | H18: FIRM E | I18: FIRM F | J18: FIRM G
B19: Assets | C19: Cash
C20: Short-term securities
C21: Receivables
C22: Inventory
C23: Plant and Equipment
C24: Accumulated Depreciation
C25: Total Assets
B26: Liabilities | C26: Accounts Payable
C27: Short Term Debt
C28: Long Term Debt
C29: Total Liabilities
B30: Equity | C30: Stock ($1 par)
C31: Add'l Paid in Cap.
C32: Retained Earnings
C33: Treasury Stock
C34: Total Equity
B35: Inventory Detail | C35: Beg. Inventory
C36: End. Inventory
C37: Avg. Inventory | D37: =SUM(D35:D36)/2 -> 0 | E37: =SUM(E35:E36)/2 -> 0 | F37: =SUM(F35:F36)/2 -> 0 | G37: =SUM(G35:G36)/2 -> 0 | H37: =SUM(H35:H36)/2 -> 0 | I37: =SUM(I35:I36)/2 -> 0 | J37: =SUM(J35:J36)/2 -> 0
B38: Cash Flow | C38: MILLIONS | D38: FIRM A | E38: FIRM B | F38: FIRM C | G38: FIRM D | H38: FIRM E | I38: FIRM F | J38: FIRM G
C39: Net Cash from Operations
C40: Net investment
B41: Ratios | D41: FIRM A | E41: FIRM B | F41: FIRM C | G41: FIRM D | H41: FIRM E | I41: FIRM F | J41: FIRM G
B42: Profitability | C42: Gross Profit Margin | D42: =D6/D4 -> #DIV/0! | E42: =E6/E4 -> #DIV/0! | F42: =F6/F4 -> #DIV/0! | G42: =G6/G4 -> #DIV/0! | H42: =H6/H4 -> #DIV/0! | I42: =I6/I4 -> #DIV/0! | J42: =J6/J4 -> #DIV/0!
C43: Operating Profit Margin | D43: =D10/D4 -> #DIV/0! | E43: =E10/E4 -> #DIV/0! | F43: =F10/F4 -> #DIV/0! | G43: =G10/G4 -> #DIV/0! | H43: =H10/H4 -> #DIV/0! | I43: =I10/I4 -> #DIV/0! | J43: =J10/J4 -> #DIV/0!
...

Sheet Year 7
B3: Income Statement | C3: MILLIONS | D3: FIRM A | E3: FIRM B | F3: FIRM C | G3: FIRM D | H3: FIRM E | I3: FIRM F | J3: FIRM G
C4: Sales
C5: Cost of Goods Sold
C6: Gross Margin
C7: Marketing
C8: Research and Development
C9: General and Administrative
C10: Income from Operations
C11: Interest Income
C12: Interest Expense
C13: Extraordinary Items
C14: Income before Tax
C15: Less Tax @ 35%
... C17: Dividends Paid
B18: Balance Sheet | C18: MILLIONS | D18: FIRM A | E18: FIRM B | F18: FIRM C | G18: FIRM D | H18: FIRM E | I18: FIRM F | J18: FIRM G
B19: Assets | C19: Cash
C20: Short-term securities
C21: Receivables
C22: Inventory
C23: Plant and Equipment
C24: Accumulated Depreciation
C25: Total Assets
B26: Liabilities | C26: Accounts Payable
C27: Short Term Debt
C28: Long Term Debt
C29: Total Liabilities
B30: Equity | C30: Stock ($1 par)
C31: Add'l Paid in Cap.
C32: Retained Earnings
C33: Treasury Stock
C34: Total Equity
B35: Inventory Detail | C35: Beg. Inventory
C36: End. Inventory
C37: Avg. Inventory | D37: =SUM(D35:D36)/2 -> 0 | E37: =SUM(E35:E36)/2 -> 0 | F37: =SUM(F35:F36)/2 -> 0 | G37: =SUM(G35:G36)/2 -> 0 | H37: =SUM(H35:H36)/2 -> 0 | I37: =SUM(I35:I36)/2 -> 0 | J37: =SUM(J35:J36)/2 -> 0
B38: Cash Flow | C38: MILLIONS | D38: FIRM A | E38: FIRM B | F38: FIRM C | G38: FIRM D | H38: FIRM E | I38: FIRM F | J38: FIRM G
C39: Net Cash from Operations
C40: Net investment
B41: Ratios | D41: FIRM A | E41: FIRM B | F41: FIRM C | G41: FIRM D | H41: FIRM E | I41: FIRM F | J41: FIRM G
B42: Profitability | C42: Gross Profit Margin | D42: =D6/D4 -> #DIV/0! | E42: =E6/E4 -> #DIV/0! | F42: =F6/F4 -> #DIV/0! | G42: =G6/G4 -> #DIV/0! | H42: =H6/H4 -> #DIV/0! | I42: =I6/I4 -> #DIV/0! | J42: =J6/J4 -> #DIV/0!
C43: Operating Profit Margin | D43: =D10/D4 -> #DIV/0! | E43: =E10/E4 -> #DIV/0! | F43: =F10/F4 -> #DIV/0! | G43: =G10/G4 -> #DIV/0! | H43: =H10/H4 -> #DIV/0! | I43: =I10/I4 -> #DIV/0! | J43: =J10/J4 -> #DIV/0!
...

Sheet Year 8
B3: Income Statement | C3: MILLIONS | D3: FIRM A | E3: FIRM B | F3: FIRM C | G3: FIRM D | H3: FIRM E | I3: FIRM F | J3: FIRM G
C4: Sales
C5: Cost of Goods Sold
C6: Gross Margin
C7: Marketing
C8: Research and Development
C9: General and Administrative
C10: Income from Operations
C11: Interest Income
C12: Interest Expense
C13: Extraordinary Items
C14: Income before Tax
C15: Less Tax @ 35%
... C17: Dividends Paid
B18: Balance Sheet | C18: MILLIONS | D18: FIRM A | E18: FIRM B | F18: FIRM C | G18: FIRM D | H18: FIRM E | I18: FIRM F | J18: FIRM G
B19: Assets | C19: Cash
C20: Short-term securities
C21: Receivables
C22: Inventory
C23: Plant and Equipment
C24: Accumulated Depreciation
C25: Total Assets
B26: Liabilities | C26: Accounts Payable
C27: Short Term Debt
C28: Long Term Debt
C29: Total Liabilities
B30: Equity | C30: Stock ($1 par)
C31: Add'l Paid in Cap.
C32: Retained Earnings
C33: Treasury Stock
C34: Total Equity
B35: Inventory Detail | C35: Beg. Inventory
C36: End. Inventory
C37: Avg. Inventory | D37: =SUM(D35:D36)/2 -> 0 | E37: =SUM(E35:E36)/2 -> 0 | F37: =SUM(F35:F36)/2 -> 0 | G37: =SUM(G35:G36)/2 -> 0 | H37: =SUM(H35:H36)/2 -> 0 | I37: =SUM(I35:I36)/2 -> 0 | J37: =SUM(J35:J36)/2 -> 0
B38: Cash Flow | C38: MILLIONS | D38: FIRM A | E38: FIRM B | F38: FIRM C | G38: FIRM D | H38: FIRM E | I38: FIRM F | J38: FIRM G
C39: Net Cash from Operations
C40: Net investment
B41: Ratios | D41: FIRM A | E41: FIRM B | F41: FIRM C | G41: FIRM D | H41: FIRM E | I41: FIRM F | J41: FIRM G
B42: Profitability | C42: Gross Profit Margin | D42: =D6/D4 -> #DIV/0! | E42: =E6/E4 -> #DIV/0! | F42: =F6/F4 -> #DIV/0! | G42: =G6/G4 -> #DIV/0! | H42: =H6/H4 -> #DIV/0! | I42: =I6/I4 -> #DIV/0! | J42: =J6/J4 -> #DIV/0!
C43: Operating Profit Margin | D43: =D10/D4 -> #DIV/0! | E43: =E10/E4 -> #DIV/0! | F43: =F10/F4 -> #DIV/0! | G43: =G10/G4 -> #DIV/0! | H43: =H10/H4 -> #DIV/0! | I43: =I10/I4 -> #DIV/0! | J43: =J10/J4 -> #DIV/0!
...
